<?xml version="1.0" ?>
<robot name="bioin_sensor">
  <link name="base_link">
    <inertial>
      <mass value="100"/>
      <origin xyz="0 0 0" rpy="0 0 0"/>
      <inertia ixx="0.00711749" ixy="0" ixz="0" iyy="0.00711749" iyz="0" izz="0.0141333"/>
    </inertial>
    <collision>
      <origin xyz="0 0 0" rpy="0 0 0"/>
      <geometry>
        <box size="1 1 0.08"/>
      </geometry>
    </collision>
    <visual>
      <origin xyz="0 0 0" rpy="0 0 0"/>
      <geometry>
        <box size="0.8 0.8 0.1"/>
      </geometry>
    </visual>
  </link>
  <link name="virtual_link_1">
    <inertial>
      <mass value="0.00456564"/>
      <origin xyz="0 0 0" rpy="0 0 0"/>
      <inertia ixx="1.256e-05" ixy="0" ixz="0" iyy="1.256e-05" iyz="0" izz="1.256e-05"/>
    </inertial>
    <collision>
      <origin xyz="0 0 0" rpy="0 0 0"/>
      <geometry>
        <sphere radius="0.082945"/>
      </geometry>
    </collision>
    <visual>
      <origin xyz="0 0 0" rpy="0 0 0"/>
      <geometry>
        <sphere radius="0.0001"/>
      </geometry>
    </visual>
  </link>
  <link name="virtual_link_2">
    <inertial>
      <mass value="0.00456564"/>
      <origin xyz="0 0 0" rpy="0 0 0"/>
      <inertia ixx="1.256e-05" ixy="0" ixz="0" iyy="1.256e-05" iyz="0" izz="1.256e-05"/>
    </inertial>
    <collision>
      <origin xyz="0 0 0" rpy="0 0 0"/>
      <geometry>
        <sphere radius="0.082945"/>
      </geometry>
    </collision>
    <visual>
      <origin xyz="0 0 0" rpy="0 0 0"/>
      <geometry>
        <sphere radius="0.0001"/>
      </geometry>
    </visual>
  </link>
  <link name="virtual_link_3">
    <inertial>
      <mass value="0.00809968"/>
      <origin xyz="0 0 0" rpy="0 0 0"/>
      <inertia ixx="6.43688e-05" ixy="0" ixz="0" iyy="6.43688e-05" iyz="0" izz="3.04428e-05"/>
    </inertial>
    <collision>
      <origin xyz="0 0 0" rpy="0 0 0"/>
      <geometry>
        <cylinder radius="0.086701" length="0.26984"/>
      </geometry>
    </collision>
    <visual>
      <origin xyz="0 0 0" rpy="0 0 0"/>
      <geometry>
        <cylinder radius="0.0867008" length="0.85"/>
      </geometry>
    </visual>
  </link>
  <link name="top_link">
    <inertial>
      <mass value="0.1"/>
      <origin xyz="0 0 0" rpy="0 0 0"/>
      <inertia ixx="0.00662949" ixy="0" ixz="0" iyy="0.00662949" iyz="0" izz="0.0130685"/>
    </inertial>
    <collision>
      <origin xyz="0 0 0" rpy="0 0 0"/>
      <geometry>
        <cylinder radius="0.5" length="0.1"/>
      </geometry>
    </collision>
    <visual>
      <origin xyz="0 0 0" rpy="0 0 0"/>
      <geometry>
        <cylinder radius="0.4" length="0.2"/>
      </geometry>
    </visual>
  </link>
  <link name="subbase_link">
    <inertial>
      <mass value="100"/>
      <origin xyz="0 0 0" rpy="0 0 0"/>
      <inertia ixx="0.00711749" ixy="0" ixz="0" iyy="0.00711749" iyz="0" izz="0.0141333"/>
    </inertial>
    <collision>
      <origin xyz="0 0 0.04" rpy="0 0 0"/>
      <geometry>
        <box size="1 1 0.08"/>
      </geometry>
    </collision>
    <visual>
      <origin xyz="0 0 0.04" rpy="0 0 0"/>
      <geometry>
        <box size="0.8 0.8 0.1"/>
      </geometry>
    </visual>
  </link>
  <joint name="rev_x_joint" type="revolute">
    <parent link="base_link"/>
    <child link="virtual_link_1"/>
    <origin xyz="0 0 -0.02" rpy="0 0 0"/>
    <axis xyz="1 0 0"/>
    <limit lower="-1.5708" upper="1.5708" effort="-1.0" velocity="-1.0"/>
    <dynamics damping="1.0" friction="0.0"/>
  </joint>
  <joint name="rev_y_joint" type="revolute">
    <parent link="virtual_link_1"/>
    <child link="virtual_link_2"/>
    <origin xyz="0 0 0.1" rpy="0 0 0"/>
    <axis xyz="0 1 0"/>
    <limit lower="-1.5708" upper="1.5708" effort="-1.0" velocity="-1.0"/>
    <dynamics damping="1.0" friction="0.0"/>
  </joint>
  <joint name="rev_z_joint" type="revolute">
    <parent link="virtual_link_2"/>
    <child link="virtual_link_3"/>
    <origin xyz="0 0 0.3991" rpy="0 0 0"/>
    <axis xyz="0 0 1"/>
    <limit lower="-1.5708" upper="1.5708" effort="-1.0" velocity="-1.0"/>
    <dynamics damping="1.0" friction="0.0"/>
  </joint>
  <joint name="prismatic_joint" type="prismatic">
    <parent link="virtual_link_3"/>
    <child link="top_link"/>
    <origin xyz="0 0 0.50089" rpy="0 0 0"/>
    <axis xyz="0 0 1"/>
    <limit lower="-0.2" upper="0.2" effort="-1.0" velocity="-1.0"/>
    <dynamics damping="3.0" friction="0.0"/>
  </joint>
  <joint name="fixed_joint" type="fixed">
    <parent link="subbase_link"/>
    <child link="base_link"/>
    <origin xyz="0 0 0.12" rpy="0 0 0"/>
    <axis xyz="0 0 0"/>
    <limit lower="0" upper="0" effort="0" velocity="0"/>
  </joint>
  <gazebo reference="rev_x_joint">
    <implicitSpringDamper>True</implicitSpringDamper>
    <springReference>0</springReference>
    <springStiffness>10</springStiffness>
  </gazebo>
  <gazebo reference="rev_y_joint">
    <implicitSpringDamper>True</implicitSpringDamper>
    <springReference>0</springReference>
    <springStiffness>10</springStiffness>
  </gazebo>
  <gazebo reference="rev_z_joint">
    <implicitSpringDamper>True</implicitSpringDamper>
    <springReference>0</springReference>
    <springStiffness>10</springStiffness>
  </gazebo>
  <gazebo reference="prismatic_joint">
    <implicitSpringDamper>True</implicitSpringDamper>
    <springReference>0</springReference>
    <springStiffness>50</springStiffness>
  </gazebo>
  <gazebo>
    <plugin name="JointStatePublisher" filename="libJointStatePublisher.so">
      <publish_selected_only>true</publish_selected_only>
      <joint>prismatic_joint</joint>
    </plugin> 
  </gazebo>
  <gazebo reference="top_link">
    <gravity>true</gravity>
    <sensor name="imu_sensor" type="imu">
      <always_on>true</always_on>
      <update_rate>120</update_rate>
      <visualize>true</visualize>
      <topic>__default_topic__</topic>
      <plugin filename="libgazebo_ros_imu_sensor.so" name="imu_plugin">
        <topicName>imu</topicName>
        <bodyName>top_link</bodyName>
        <updateRateHZ>10.0</updateRateHZ>
        <gaussianNoise>0.001</gaussianNoise>
        <xyzOffset>0 0 0</xyzOffset>
        <rpyOffset>0 0 0</rpyOffset>
        <frameName>top_link</frameName>
        <initialOrientationAsReference>false</initialOrientationAsReference>
      </plugin>
      <pose>0 0 0 0 0 0</pose>
    </sensor>
  </gazebo>
</robot>